{
  "registryname": "bioreacteur",
  "localizedname": "Bio-Reacteur Manifold",
  "requires-blueprint": false,
  "parts": [
    {
      "x": -2,
      "y": -1,
      "z": -2,
      "elements": "casings_all"
    },
    {
      "x": -2,
      "y": -1,
      "z": -1,
      "elements": "casings_all"
    },
    {
      "x": -2,
      "y": -1,
      "z": 0,
      "elements": "casings_all"
    },
    {
      "x": -2,
      "y": -1,
      "z": 1,
      "elements": "casings_all"
    },
    {
      "x": -2,
      "y": -1,
      "z": 2,
      "elements": "casings_all"
    },
    {
      "x": -1,
      "y": -1,
      "z": -2,
      "elements": "casings_all"
    },
    {
      "x": -1,
      "y": -1,
      "z": -1,
      "elements": "casings_all"
    },
    {
      "x": -1,
      "y": -1,
      "z": 0,
      "elements": "casings_all"
    },
    {
      "x": -1,
      "y": -1,
      "z": 1,
      "elements": "casings_all"
    },
    {
      "x": -1,
      "y": -1,
      "z": 2,
      "elements": "casings_all"
    },
    {
      "x": 0,
      "y": -1,
      "z": -2,
      "elements": "casings_all"
    },
    {
      "x": 0,
      "y": -1,
      "z": -1,
      "elements": "casings_all"
    },
    {
      "x": 0,
      "y": -1,
      "z": 0,
      "elements": "casings_all"
    },
    {
      "x": 0,
      "y": -1,
      "z": 1,
      "elements": "casings_all"
    },
    {
      "x": 0,
      "y": -1,
      "z": 2,
      "elements": "casings_all"
    },
    {
      "x": 1,
      "y": -1,
      "z": -2,
      "elements": "casings_all"
    },
    {
      "x": 1,
      "y": -1,
      "z": -1,
      "elements": "casings_all"
    },
    {
      "x": 1,
      "y": -1,
      "z": 0,
      "elements": "casings_all"
    },
    {
      "x": 1,
      "y": -1,
      "z": 1,
      "elements": "casings_all"
    },
    {
      "x": 1,
      "y": -1,
      "z": 2,
      "elements": "casings_all"
    },
    {
      "x": 2,
      "y": -1,
      "z": -2,
      "elements": "casings_all"
    },
    {
      "x": 2,
      "y": -1,
      "z": -1,
      "elements": "casings_all"
    },
    {
      "x": 2,
      "y": -1,
      "z": 0,
      "elements": "casings_all"
    },
    {
      "x": 2,
      "y": -1,
      "z": 1,
      "elements": "casings_all"
    },
    {
      "x": 2,
      "y": -1,
      "z": 2,
      "elements": "casings_all"
    },
    {
      "x": -2,
      "y": 0,
      "z": -2,
      "elements": "contenttweaker:bioreacteur_controller"
    },
    {
      "x": -2,
      "y": 0,
      "z": -1,
      "elements": "casings_all"
    },
    {
      "x": -2,
      "y": 0,
      "z": 0,
      "elements": "modularmachinery:blockfluidinputhatch"
    },
    {
      "x": -2,
      "y": 0,
      "z": 1,
      "elements": "casings_all"
    },
    {
      "x": -2,
      "y": 0,
      "z": 2,
      "elements": "contenttweaker:bioreacteur_controller"
    },
    {
      "x": -1,
      "y": 0,
      "z": -2,
      "elements": "casings_all"
    },
    {
      "x": -1,
      "y": 0,
      "z": 2,
      "elements": "casings_all"
    },
    {
      "x": 0,
      "y": 0,
      "z": -2,
      "elements": "modularmachinery:blockinputbus"
    },
    {
      "x": 0,
      "y": 0,
      "z": 2,
      "elements": "modularmachinery:blockoutputbus"
    },
    {
      "x": 1,
      "y": 0,
      "z": -2,
      "elements": "casings_all"
    },
    {
      "x": 1,
      "y": 0,
      "z": 2,
      "elements": "casings_all"
    },
    {
      "x": 2,
      "y": 0,
      "z": -2,
      "elements": "contenttweaker:bioreacteur_controller"
    },
    {
      "x": 2,
      "y": 0,
      "z": -1,
      "elements": "casings_all"
    },
    {
      "x": 2,
      "y": 0,
      "z": 0,
      "elements": "modularmachinery:blockfluidoutputhatch"
    },
    {
      "x": 2,
      "y": 0,
      "z": 1,
      "elements": "casings_all"
    },
    {
      "x": 2,
      "y": 0,
      "z": 2,
      "elements": "contenttweaker:bioreacteur_controller"
    },
    {
      "x": -2,
      "y": 1,
      "z": -2,
      "elements": "modularmachinery:blockenergyinputhatch"
    },
    {
      "x": -2,
      "y": 1,
      "z": -1,
      "elements": "casings_all"
    },
    {
      "x": -2,
      "y": 1,
      "z": 0,
      "elements": "minecraft:glass"
    },
    {
      "x": -2,
      "y": 1,
      "z": 1,
      "elements": "casings_all"
    },
    {
      "x": -2,
      "y": 1,
      "z": 2,
      "elements": "casings_all"
    },
    {
      "x": -1,
      "y": 1,
      "z": -2,
      "elements": "casings_all"
    },
    {
      "x": -1,
      "y": 1,
      "z": 2,
      "elements": "casings_all"
    },
    {
      "x": 0,
      "y": 1,
      "z": -2,
      "elements": "minecraft:glass"
    },
    {
      "x": 0,
      "y": 1,
      "z": 2,
      "elements": "minecraft:glass"
    },
    {
      "x": 1,
      "y": 1,
      "z": -2,
      "elements": "casings_all"
    },
    {
      "x": 1,
      "y": 1,
      "z": 2,
      "elements": "casings_all"
    },
    {
      "x": 2,
      "y": 1,
      "z": -2,
      "elements": "casings_all"
    },
    {
      "x": 2,
      "y": 1,
      "z": -1,
      "elements": "casings_all"
    },
    {
      "x": 2,
      "y": 1,
      "z": 0,
      "elements": "minecraft:glass"
    },
    {
      "x": 2,
      "y": 1,
      "z": 1,
      "elements": "casings_all"
    },
    {
      "x": 2,
      "y": 1,
      "z": 2,
      "elements": "casings_all"
    },
    {
      "x": -2,
      "y": 2,
      "z": -2,
      "elements": "casings_decorative"
    },
    {
      "x": -2,
      "y": 2,
      "z": -1,
      "elements": "casings_decorative"
    },
    {
      "x": -2,
      "y": 2,
      "z": 0,
      "elements": "casings_decorative"
    },
    {
      "x": -2,
      "y": 2,
      "z": 1,
      "elements": "casings_decorative"
    },
    {
      "x": -2,
      "y": 2,
      "z": 2,
      "elements": "casings_decorative"
    },
    {
      "x": -1,
      "y": 2,
      "z": -2,
      "elements": "casings_decorative"
    },
    {
      "x": -1,
      "y": 2,
      "z": -1,
      "elements": "casings_decorative"
    },
    {
      "x": -1,
      "y": 2,
      "z": 0,
      "elements": "casings_decorative"
    },
    {
      "x": -1,
      "y": 2,
      "z": 1,
      "elements": "casings_decorative"
    },
    {
      "x": -1,
      "y": 2,
      "z": 2,
      "elements": "casings_decorative"
    },
    {
      "x": 0,
      "y": 2,
      "z": -2,
      "elements": "casings_decorative"
    },
    {
      "x": 0,
      "y": 2,
      "z": -1,
      "elements": "casings_decorative"
    },
    {
      "x": 0,
      "y": 2,
      "z": 0,
      "elements": "casings_decorative"
    },
    {
      "x": 0,
      "y": 2,
      "z": 1,
      "elements": "casings_decorative"
    },
    {
      "x": 0,
      "y": 2,
      "z": 2,
      "elements": "casings_decorative"
    },
    {
      "x": 1,
      "y": 2,
      "z": -2,
      "elements": "casings_decorative"
    },
    {
      "x": 1,
      "y": 2,
      "z": -1,
      "elements": "casings_decorative"
    },
    {
      "x": 1,
      "y": 2,
      "z": 0,
      "elements": "casings_decorative"
    },
    {
      "x": 1,
      "y": 2,
      "z": 1,
      "elements": "casings_decorative"
    },
    {
      "x": 1,
      "y": 2,
      "z": 2,
      "elements": "casings_decorative"
    },
    {
      "x": 2,
      "y": 2,
      "z": -2,
      "elements": "casings_decorative"
    },
    {
      "x": 2,
      "y": 2,
      "z": -1,
      "elements": "casings_decorative"
    },
    {
      "x": 2,
      "y": 2,
      "z": 0,
      "elements": "casings_decorative"
    },
    {
      "x": 2,
      "y": 2,
      "z": 1,
      "elements": "casings_decorative"
    },
    {
      "x": 2,
      "y": 2,
      "z": 2,
      "elements": "casings_decorative"
    }
  ]
}