{
  "registryname": "cryo_distillateur",
  "localizedname": "Cryo-Distillateur Atmospherique",
  "requires-blueprint": false,
  "parts": [
    {
      "x": -3,
      "y": -1,
      "z": -2,
      "elements": "casings_all"
    },
    {
      "x": -3,
      "y": -1,
      "z": -1,
      "elements": "casings_all"
    },
    {
      "x": -3,
      "y": -1,
      "z": 0,
      "elements": "casings_all"
    },
    {
      "x": -3,
      "y": -1,
      "z": 1,
      "elements": "casings_all"
    },
    {
      "x": -3,
      "y": -1,
      "z": 2,
      "elements": "casings_all"
    },
    {
      "x": -2,
      "y": -1,
      "z": -2,
      "elements": "casings_all"
    },
    {
      "x": -2,
      "y": -1,
      "z": -1,
      "elements": "casings_all"
    },
    {
      "x": -2,
      "y": -1,
      "z": 0,
      "elements": "casings_all"
    },
    {
      "x": -2,
      "y": -1,
      "z": 1,
      "elements": "casings_all"
    },
    {
      "x": -2,
      "y": -1,
      "z": 2,
      "elements": "casings_all"
    },
    {
      "x": -1,
      "y": -1,
      "z": -2,
      "elements": "casings_all"
    },
    {
      "x": -1,
      "y": -1,
      "z": -1,
      "elements": "casings_all"
    },
    {
      "x": -1,
      "y": -1,
      "z": 0,
      "elements": "casings_all"
    },
    {
      "x": -1,
      "y": -1,
      "z": 1,
      "elements": "casings_all"
    },
    {
      "x": -1,
      "y": -1,
      "z": 2,
      "elements": "casings_all"
    },
    {
      "x": 0,
      "y": -1,
      "z": -2,
      "elements": "casings_all"
    },
    {
      "x": 0,
      "y": -1,
      "z": -1,
      "elements": "casings_all"
    },
    {
      "x": 0,
      "y": -1,
      "z": 0,
      "elements": "casings_all"
    },
    {
      "x": 0,
      "y": -1,
      "z": 1,
      "elements": "casings_all"
    },
    {
      "x": 0,
      "y": -1,
      "z": 2,
      "elements": "casings_all"
    },
    {
      "x": 1,
      "y": -1,
      "z": -2,
      "elements": "casings_all"
    },
    {
      "x": 1,
      "y": -1,
      "z": -1,
      "elements": "casings_all"
    },
    {
      "x": 1,
      "y": -1,
      "z": 0,
      "elements": "casings_all"
    },
    {
      "x": 1,
      "y": -1,
      "z": 1,
      "elements": "casings_all"
    },
    {
      "x": 1,
      "y": -1,
      "z": 2,
      "elements": "casings_all"
    },
    {
      "x": 2,
      "y": -1,
      "z": -2,
      "elements": "casings_all"
    },
    {
      "x": 2,
      "y": -1,
      "z": -1,
      "elements": "casings_all"
    },
    {
      "x": 2,
      "y": -1,
      "z": 0,
      "elements": "casings_all"
    },
    {
      "x": 2,
      "y": -1,
      "z": 1,
      "elements": "casings_all"
    },
    {
      "x": 2,
      "y": -1,
      "z": 2,
      "elements": "casings_all"
    },
    {
      "x": 3,
      "y": -1,
      "z": -2,
      "elements": "casings_all"
    },
    {
      "x": 3,
      "y": -1,
      "z": -1,
      "elements": "casings_all"
    },
    {
      "x": 3,
      "y": -1,
      "z": 0,
      "elements": "casings_all"
    },
    {
      "x": 3,
      "y": -1,
      "z": 1,
      "elements": "casings_all"
    },
    {
      "x": 3,
      "y": -1,
      "z": 2,
      "elements": "casings_all"
    },
    {
      "x": -3,
      "y": 0,
      "z": -2,
      "elements": "contenttweaker:cryo_distillateur_controller"
    },
    {
      "x": -3,
      "y": 0,
      "z": -1,
      "elements": "casings_all"
    },
    {
      "x": -3,
      "y": 0,
      "z": 0,
      "elements": "casings_all"
    },
    {
      "x": -3,
      "y": 0,
      "z": 1,
      "elements": "casings_all"
    },
    {
      "x": -3,
      "y": 0,
      "z": 2,
      "elements": "contenttweaker:cryo_distillateur_controller"
    },
    {
      "x": -2,
      "y": 0,
      "z": -2,
      "elements": "casings_all"
    },
    {
      "x": -2,
      "y": 0,
      "z": -1,
      "elements": "minecraft:iron_block"
    },
    {
      "x": -2,
      "y": 0,
      "z": 0,
      "elements": "casings_all"
    },
    {
      "x": -2,
      "y": 0,
      "z": 1,
      "elements": "minecraft:iron_block"
    },
    {
      "x": -2,
      "y": 0,
      "z": 2,
      "elements": "casings_all"
    },
    {
      "x": -1,
      "y": 0,
      "z": -2,
      "elements": "casings_all"
    },
    {
      "x": -1,
      "y": 0,
      "z": -1,
      "elements": "casings_all"
    },
    {
      "x": -1,
      "y": 0,
      "z": 0,
      "elements": "modularmachinery:blockfluidinputhatch"
    },
    {
      "x": -1,
      "y": 0,
      "z": 1,
      "elements": "casings_all"
    },
    {
      "x": -1,
      "y": 0,
      "z": 2,
      "elements": "casings_all"
    },
    {
      "x": 0,
      "y": 0,
      "z": -2,
      "elements": "casings_all"
    },
    {
      "x": 0,
      "y": 0,
      "z": -1,
      "elements": "modularmachinery:blockfluidinputhatch"
    },
    {
      "x": 0,
      "y": 0,
      "z": 1,
      "elements": "modularmachinery:blockfluidinputhatch"
    },
    {
      "x": 0,
      "y": 0,
      "z": 2,
      "elements": "casings_all"
    },
    {
      "x": 1,
      "y": 0,
      "z": -2,
      "elements": "casings_all"
    },
    {
      "x": 1,
      "y": 0,
      "z": -1,
      "elements": "casings_all"
    },
    {
      "x": 1,
      "y": 0,
      "z": 0,
      "elements": "modularmachinery:blockfluidinputhatch"
    },
    {
      "x": 1,
      "y": 0,
      "z": 1,
      "elements": "casings_all"
    },
    {
      "x": 1,
      "y": 0,
      "z": 2,
      "elements": "casings_all"
    },
    {
      "x": 2,
      "y": 0,
      "z": -2,
      "elements": "casings_all"
    },
    {
      "x": 2,
      "y": 0,
      "z": -1,
      "elements": "minecraft:iron_block"
    },
    {
      "x": 2,
      "y": 0,
      "z": 0,
      "elements": "casings_all"
    },
    {
      "x": 2,
      "y": 0,
      "z": 1,
      "elements": "minecraft:iron_block"
    },
    {
      "x": 2,
      "y": 0,
      "z": 2,
      "elements": "casings_all"
    },
    {
      "x": 3,
      "y": 0,
      "z": -2,
      "elements": "contenttweaker:cryo_distillateur_controller"
    },
    {
      "x": 3,
      "y": 0,
      "z": -1,
      "elements": "casings_all"
    },
    {
      "x": 3,
      "y": 0,
      "z": 0,
      "elements": "casings_all"
    },
    {
      "x": 3,
      "y": 0,
      "z": 1,
      "elements": "casings_all"
    },
    {
      "x": 3,
      "y": 0,
      "z": 2,
      "elements": "contenttweaker:cryo_distillateur_controller"
    },
    {
      "x": -1,
      "y": 1,
      "z": -1,
      "elements": "casings_all"
    },
    {
      "x": -1,
      "y": 1,
      "z": 0,
      "elements": "casings_all"
    },
    {
      "x": -1,
      "y": 1,
      "z": 1,
      "elements": "casings_all"
    },
    {
      "x": 0,
      "y": 1,
      "z": -1,
      "elements": "casings_all"
    },
    {
      "x": 0,
      "y": 1,
      "z": 1,
      "elements": "casings_all"
    },
    {
      "x": 1,
      "y": 1,
      "z": -1,
      "elements": "casings_all"
    },
    {
      "x": 1,
      "y": 1,
      "z": 0,
      "elements": "casings_all"
    },
    {
      "x": 1,
      "y": 1,
      "z": 1,
      "elements": "casings_all"
    },
    {
      "x": -1,
      "y": 2,
      "z": -1,
      "elements": "casings_all"
    },
    {
      "x": -1,
      "y": 2,
      "z": 0,
      "elements": "minecraft:glass"
    },
    {
      "x": -1,
      "y": 2,
      "z": 1,
      "elements": "casings_all"
    },
    {
      "x": 0,
      "y": 2,
      "z": -1,
      "elements": "minecraft:glass"
    },
    {
      "x": 0,
      "y": 2,
      "z": 1,
      "elements": "minecraft:glass"
    },
    {
      "x": 1,
      "y": 2,
      "z": -1,
      "elements": "casings_all"
    },
    {
      "x": 1,
      "y": 2,
      "z": 0,
      "elements": "minecraft:glass"
    },
    {
      "x": 1,
      "y": 2,
      "z": 1,
      "elements": "casings_all"
    },
    {
      "x": -1,
      "y": 3,
      "z": -1,
      "elements": "casings_all"
    },
    {
      "x": -1,
      "y": 3,
      "z": 0,
      "elements": "casings_all"
    },
    {
      "x": -1,
      "y": 3,
      "z": 1,
      "elements": "casings_all"
    },
    {
      "x": 0,
      "y": 3,
      "z": -1,
      "elements": "casings_all"
    },
    {
      "x": 0,
      "y": 3,
      "z": 1,
      "elements": "casings_all"
    },
    {
      "x": 1,
      "y": 3,
      "z": -1,
      "elements": "casings_all"
    },
    {
      "x": 1,
      "y": 3,
      "z": 0,
      "elements": "casings_all"
    },
    {
      "x": 1,
      "y": 3,
      "z": 1,
      "elements": "casings_all"
    },
    {
      "x": -1,
      "y": 4,
      "z": -1,
      "elements": "casings_all"
    },
    {
      "x": -1,
      "y": 4,
      "z": 0,
      "elements": "minecraft:glass"
    },
    {
      "x": -1,
      "y": 4,
      "z": 1,
      "elements": "casings_all"
    },
    {
      "x": 0,
      "y": 4,
      "z": -1,
      "elements": "minecraft:glass"
    },
    {
      "x": 0,
      "y": 4,
      "z": 1,
      "elements": "minecraft:glass"
    },
    {
      "x": 1,
      "y": 4,
      "z": -1,
      "elements": "casings_all"
    },
    {
      "x": 1,
      "y": 4,
      "z": 0,
      "elements": "minecraft:glass"
    },
    {
      "x": 1,
      "y": 4,
      "z": 1,
      "elements": "casings_all"
    },
    {
      "x": -1,
      "y": 5,
      "z": -1,
      "elements": "casings_all"
    },
    {
      "x": -1,
      "y": 5,
      "z": 0,
      "elements": "casings_all"
    },
    {
      "x": -1,
      "y": 5,
      "z": 1,
      "elements": "casings_all"
    },
    {
      "x": 0,
      "y": 5,
      "z": -1,
      "elements": "casings_all"
    },
    {
      "x": 0,
      "y": 5,
      "z": 1,
      "elements": "casings_all"
    },
    {
      "x": 1,
      "y": 5,
      "z": -1,
      "elements": "casings_all"
    },
    {
      "x": 1,
      "y": 5,
      "z": 0,
      "elements": "casings_all"
    },
    {
      "x": 1,
      "y": 5,
      "z": 1,
      "elements": "casings_all"
    },
    {
      "x": -1,
      "y": 6,
      "z": -1,
      "elements": "casings_all"
    },
    {
      "x": -1,
      "y": 6,
      "z": 0,
      "elements": "minecraft:glass"
    },
    {
      "x": -1,
      "y": 6,
      "z": 1,
      "elements": "casings_all"
    },
    {
      "x": 0,
      "y": 6,
      "z": -1,
      "elements": "minecraft:glass"
    },
    {
      "x": 0,
      "y": 6,
      "z": 1,
      "elements": "minecraft:glass"
    },
    {
      "x": 1,
      "y": 6,
      "z": -1,
      "elements": "casings_all"
    },
    {
      "x": 1,
      "y": 6,
      "z": 0,
      "elements": "minecraft:glass"
    },
    {
      "x": 1,
      "y": 6,
      "z": 1,
      "elements": "casings_all"
    },
    {
      "x": -1,
      "y": 7,
      "z": -1,
      "elements": "casings_all"
    },
    {
      "x": -1,
      "y": 7,
      "z": 0,
      "elements": "casings_all"
    },
    {
      "x": -1,
      "y": 7,
      "z": 1,
      "elements": "casings_all"
    },
    {
      "x": 0,
      "y": 7,
      "z": -1,
      "elements": "casings_all"
    },
    {
      "x": 0,
      "y": 7,
      "z": 1,
      "elements": "casings_all"
    },
    {
      "x": 1,
      "y": 7,
      "z": -1,
      "elements": "casings_all"
    },
    {
      "x": 1,
      "y": 7,
      "z": 0,
      "elements": "casings_all"
    },
    {
      "x": 1,
      "y": 7,
      "z": 1,
      "elements": "casings_all"
    },
    {
      "x": -1,
      "y": 8,
      "z": -1,
      "elements": "casings_all"
    },
    {
      "x": -1,
      "y": 8,
      "z": 0,
      "elements": "minecraft:glass"
    },
    {
      "x": -1,
      "y": 8,
      "z": 1,
      "elements": "casings_all"
    },
    {
      "x": 0,
      "y": 8,
      "z": -1,
      "elements": "minecraft:glass"
    },
    {
      "x": 0,
      "y": 8,
      "z": 1,
      "elements": "minecraft:glass"
    },
    {
      "x": 1,
      "y": 8,
      "z": -1,
      "elements": "casings_all"
    },
    {
      "x": 1,
      "y": 8,
      "z": 0,
      "elements": "minecraft:glass"
    },
    {
      "x": 1,
      "y": 8,
      "z": 1,
      "elements": "casings_all"
    },
    {
      "x": -1,
      "y": 9,
      "z": -1,
      "elements": "casings_all"
    },
    {
      "x": -1,
      "y": 9,
      "z": 0,
      "elements": "casings_all"
    },
    {
      "x": -1,
      "y": 9,
      "z": 1,
      "elements": "casings_all"
    },
    {
      "x": 0,
      "y": 9,
      "z": -1,
      "elements": "casings_all"
    },
    {
      "x": 0,
      "y": 9,
      "z": 0,
      "elements": "modularmachinery:blockfluidoutputhatch"
    },
    {
      "x": 0,
      "y": 9,
      "z": 1,
      "elements": "casings_all"
    },
    {
      "x": 1,
      "y": 9,
      "z": -1,
      "elements": "casings_all"
    },
    {
      "x": 1,
      "y": 9,
      "z": 0,
      "elements": "casings_all"
    },
    {
      "x": 1,
      "y": 9,
      "z": 1,
      "elements": "casings_all"
    },
    {
      "x": -1,
      "y": 10,
      "z": -1,
      "elements": "casings_decorative"
    },
    {
      "x": -1,
      "y": 10,
      "z": 0,
      "elements": "casings_decorative"
    },
    {
      "x": -1,
      "y": 10,
      "z": 1,
      "elements": "casings_decorative"
    },
    {
      "x": 0,
      "y": 10,
      "z": -1,
      "elements": "casings_decorative"
    },
    {
      "x": 0,
      "y": 10,
      "z": 0,
      "elements": "casings_decorative"
    },
    {
      "x": 0,
      "y": 10,
      "z": 1,
      "elements": "casings_decorative"
    },
    {
      "x": 1,
      "y": 10,
      "z": -1,
      "elements": "casings_decorative"
    },
    {
      "x": 1,
      "y": 10,
      "z": 0,
      "elements": "casings_decorative"
    },
    {
      "x": 1,
      "y": 10,
      "z": 1,
      "elements": "casings_decorative"
    }
  ]
}